Traceback (most recent call last):
  File "E:\dev\wPCC_pipeline\venv\lib\site-packages\jupyter_cache\executors\utils.py", line 56, in single_nb_execution
    record_timing=False,
  File "E:\dev\wPCC_pipeline\venv\lib\site-packages\nbclient\client.py", line 1093, in execute
    return NotebookClient(nb=nb, resources=resources, km=km, **kwargs).execute()
  File "E:\dev\wPCC_pipeline\venv\lib\site-packages\nbclient\util.py", line 84, in wrapped
    return just_run(coro(*args, **kwargs))
  File "E:\dev\wPCC_pipeline\venv\lib\site-packages\nbclient\util.py", line 62, in just_run
    return loop.run_until_complete(coro)
  File "C:\Python37-64\lib\asyncio\base_events.py", line 587, in run_until_complete
    return future.result()
  File "E:\dev\wPCC_pipeline\venv\lib\site-packages\nbclient\client.py", line 560, in async_execute
    cell, index, execution_count=self.code_cells_executed + 1
  File "E:\dev\wPCC_pipeline\venv\lib\site-packages\nbclient\client.py", line 854, in async_execute_cell
    self._check_raise_for_error(cell, exec_reply)
  File "E:\dev\wPCC_pipeline\venv\lib\site-packages\nbclient\client.py", line 756, in _check_raise_for_error
    raise CellExecutionError.from_cell_and_msg(cell, exec_reply_content)
nbclient.exceptions.CellExecutionError: An error occurred while executing the following cell:
------------------
# %load imports.py
%load_ext autoreload
%autoreload 2
%config Completer.use_jedi = False  ## (To fix autocomplete)

import pandas as pd
from src.models.vmm import ModelSimulator
import matplotlib.pyplot as plt
import matplotlib
plt.style.use('presentation')
matplotlib.rcParams["xtick.labelsize"] = 16
from src.visualization.plot import track_plots, plot, captive_plot
import kedro
import numpy as np
import os.path
import anyconfig


from myst_nb import glue
from src.symbols import *
import src.symbols as symbols
from src.system_equations import *

from IPython.display import display, Math, Latex, Markdown
from sympy.physics.vector.printing import vpprint, vlatex

from src.models.regression import MotionRegression

from src.parameters import df_parameters
from src.substitute_dynamic_symbols import run
from src.models.diff_eq_to_matrix import DiffEqToMatrix
p = df_parameters["symbol"]
import statsmodels.api as sm

# Read configs:
conf_path = os.path.join("../../conf/base/")
runs_globals_path = os.path.join(
    conf_path,
    "runs_globals.yml",
)

runs_globals = anyconfig.load(runs_globals_path)
model_test_ids = runs_globals["model_test_ids"]

join_globals_path = os.path.join(
    conf_path,
    "join_globals.yml",
)

joins = runs_globals["joins"]
join_runs_dict = anyconfig.load(join_globals_path)

globals_path = os.path.join(
    conf_path,
    "globals.yml",
)
global_variables = anyconfig.load(globals_path)



vmm_names = global_variables["vmms"]
only_joined = global_variables[
    "only_joined"
]  # (regress/predict with only models from joined runs)S

vmms = {}
for vmm_name in vmm_names:
    vmms[vmm_name] = catalog.load(vmm_name)

------------------

[1;31m---------------------------------------------------------------------------[0m
[1;31mNameError[0m                                 Traceback (most recent call last)
[1;32m~\AppData\Local\Temp/ipykernel_8496/3503003662.py[0m in [0;36m<module>[1;34m[0m
[0;32m     66[0m [0mvmms[0m [1;33m=[0m [1;33m{[0m[1;33m}[0m[1;33m[0m[1;33m[0m[0m
[0;32m     67[0m [1;32mfor[0m [0mvmm_name[0m [1;32min[0m [0mvmm_names[0m[1;33m:[0m[1;33m[0m[1;33m[0m[0m
[1;32m---> 68[1;33m     [0mvmms[0m[1;33m[[0m[0mvmm_name[0m[1;33m][0m [1;33m=[0m [0mcatalog[0m[1;33m.[0m[0mload[0m[1;33m([0m[0mvmm_name[0m[1;33m)[0m[1;33m[0m[1;33m[0m[0m
[0m
[1;31mNameError[0m: name 'catalog' is not defined
NameError: name 'catalog' is not defined

